{
  "nbformat": 4,
  "nbformat_minor": 0,
  "metadata": {
    "colab": {
      "name": "Untitled353.ipynb",
      "provenance": [],
      "collapsed_sections": [],
      "authorship_tag": "ABX9TyN45AUBWQVPOc2XwE3dDgW9",
      "include_colab_link": true
    },
    "kernelspec": {
      "name": "python3",
      "display_name": "Python 3"
    },
    "language_info": {
      "name": "python"
    },
    "accelerator": "GPU",
    "gpuClass": "standard"
  },
  "cells": [
    {
      "cell_type": "markdown",
      "metadata": {
        "id": "view-in-github",
        "colab_type": "text"
      },
      "source": [
        "<a href=\"https://colab.research.google.com/github/mohripan/Machine-Learning/blob/main/DownloadDatasetFromKaggle.ipynb\" target=\"_parent\"><img src=\"https://colab.research.google.com/assets/colab-badge.svg\" alt=\"Open In Colab\"/></a>"
      ]
    },
    {
      "cell_type": "code",
      "execution_count": null,
      "metadata": {
        "colab": {
          "base_uri": "https://localhost:8080/"
        },
        "id": "rT6wxbsinswA",
        "outputId": "5b285e45-f0cc-4fff-eb04-18ba1d3acd99"
      },
      "outputs": [
        {
          "output_type": "stream",
          "name": "stdout",
          "text": [
            "\u001b[K     |████████████████████████████████| 116 kB 5.1 MB/s \n",
            "\u001b[K     |████████████████████████████████| 60.9 MB 1.6 MB/s \n",
            "\u001b[?25hLooking in indexes: https://pypi.org/simple, https://us-python.pkg.dev/colab-wheels/public/simple/\n",
            "Collecting qudida\n",
            "  Downloading qudida-0.0.4-py3-none-any.whl (3.5 kB)\n",
            "Requirement already satisfied: typing-extensions in /usr/local/lib/python3.7/dist-packages (from qudida) (4.1.1)\n",
            "Collecting opencv-python-headless>=4.0.1\n",
            "  Downloading opencv_python_headless-4.6.0.66-cp36-abi3-manylinux_2_17_x86_64.manylinux2014_x86_64.whl (48.3 MB)\n",
            "\u001b[K     |█████████████████████▏          | 31.9 MB 1.2 MB/s eta 0:00:14\u001b[31mERROR: Exception:\n",
            "Traceback (most recent call last):\n",
            "  File \"/usr/local/lib/python3.7/dist-packages/pip/_internal/cli/base_command.py\", line 180, in _main\n",
            "    status = self.run(options, args)\n",
            "  File \"/usr/local/lib/python3.7/dist-packages/pip/_internal/cli/req_command.py\", line 199, in wrapper\n",
            "    return func(self, options, args)\n",
            "  File \"/usr/local/lib/python3.7/dist-packages/pip/_internal/commands/install.py\", line 319, in run\n",
            "    reqs, check_supported_wheels=not options.target_dir\n",
            "  File \"/usr/local/lib/python3.7/dist-packages/pip/_internal/resolution/resolvelib/resolver.py\", line 128, in resolve\n",
            "    requirements, max_rounds=try_to_avoid_resolution_too_deep\n",
            "  File \"/usr/local/lib/python3.7/dist-packages/pip/_vendor/resolvelib/resolvers.py\", line 473, in resolve\n",
            "    state = resolution.resolve(requirements, max_rounds=max_rounds)\n",
            "  File \"/usr/local/lib/python3.7/dist-packages/pip/_vendor/resolvelib/resolvers.py\", line 367, in resolve\n",
            "    failure_causes = self._attempt_to_pin_criterion(name)\n",
            "  File \"/usr/local/lib/python3.7/dist-packages/pip/_vendor/resolvelib/resolvers.py\", line 213, in _attempt_to_pin_criterion\n",
            "    criteria = self._get_criteria_to_update(candidate)\n",
            "  File \"/usr/local/lib/python3.7/dist-packages/pip/_vendor/resolvelib/resolvers.py\", line 203, in _get_criteria_to_update\n",
            "    name, crit = self._merge_into_criterion(r, parent=candidate)\n",
            "  File \"/usr/local/lib/python3.7/dist-packages/pip/_vendor/resolvelib/resolvers.py\", line 172, in _merge_into_criterion\n",
            "    if not criterion.candidates:\n",
            "  File \"/usr/local/lib/python3.7/dist-packages/pip/_vendor/resolvelib/structs.py\", line 139, in __bool__\n",
            "    return bool(self._sequence)\n",
            "  File \"/usr/local/lib/python3.7/dist-packages/pip/_internal/resolution/resolvelib/found_candidates.py\", line 143, in __bool__\n",
            "    return any(self)\n",
            "  File \"/usr/local/lib/python3.7/dist-packages/pip/_internal/resolution/resolvelib/found_candidates.py\", line 129, in <genexpr>\n",
            "    return (c for c in iterator if id(c) not in self._incompatible_ids)\n",
            "  File \"/usr/local/lib/python3.7/dist-packages/pip/_internal/resolution/resolvelib/found_candidates.py\", line 33, in _iter_built\n",
            "    candidate = func()\n",
            "  File \"/usr/local/lib/python3.7/dist-packages/pip/_internal/resolution/resolvelib/factory.py\", line 205, in _make_candidate_from_link\n",
            "    version=version,\n",
            "  File \"/usr/local/lib/python3.7/dist-packages/pip/_internal/resolution/resolvelib/candidates.py\", line 312, in __init__\n",
            "    version=version,\n",
            "  File \"/usr/local/lib/python3.7/dist-packages/pip/_internal/resolution/resolvelib/candidates.py\", line 151, in __init__\n",
            "    self.dist = self._prepare()\n",
            "  File \"/usr/local/lib/python3.7/dist-packages/pip/_internal/resolution/resolvelib/candidates.py\", line 234, in _prepare\n",
            "    dist = self._prepare_distribution()\n",
            "  File \"/usr/local/lib/python3.7/dist-packages/pip/_internal/resolution/resolvelib/candidates.py\", line 318, in _prepare_distribution\n",
            "    self._ireq, parallel_builds=True\n",
            "  File \"/usr/local/lib/python3.7/dist-packages/pip/_internal/operations/prepare.py\", line 508, in prepare_linked_requirement\n",
            "    return self._prepare_linked_requirement(req, parallel_builds)\n",
            "  File \"/usr/local/lib/python3.7/dist-packages/pip/_internal/operations/prepare.py\", line 552, in _prepare_linked_requirement\n",
            "    self.download_dir, hashes\n",
            "  File \"/usr/local/lib/python3.7/dist-packages/pip/_internal/operations/prepare.py\", line 243, in unpack_url\n",
            "    hashes=hashes,\n",
            "  File \"/usr/local/lib/python3.7/dist-packages/pip/_internal/operations/prepare.py\", line 102, in get_http_url\n",
            "    from_path, content_type = download(link, temp_dir.path)\n",
            "  File \"/usr/local/lib/python3.7/dist-packages/pip/_internal/network/download.py\", line 157, in __call__\n",
            "    for chunk in chunks:\n",
            "  File \"/usr/local/lib/python3.7/dist-packages/pip/_internal/cli/progress_bars.py\", line 156, in iter\n",
            "    self.next(len(x))  # noqa: B305\n",
            "  File \"/usr/local/lib/python3.7/dist-packages/pip/_vendor/progress/__init__.py\", line 120, in next\n",
            "    self.update()\n",
            "  File \"/usr/local/lib/python3.7/dist-packages/pip/_vendor/progress/bar.py\", line 83, in update\n",
            "    self.writeln(line)\n",
            "  File \"/usr/local/lib/python3.7/dist-packages/pip/_vendor/progress/__init__.py\", line 101, in writeln\n",
            "    self.clearln()\n",
            "  File \"/usr/local/lib/python3.7/dist-packages/pip/_vendor/progress/__init__.py\", line 90, in clearln\n",
            "    print('\\r\\x1b[K', end='', file=self.file)\n",
            "  File \"/usr/local/lib/python3.7/dist-packages/pip/_internal/cli/progress_bars.py\", line 106, in handle_sigint\n",
            "    self.finish()\n",
            "  File \"/usr/local/lib/python3.7/dist-packages/pip/_internal/cli/progress_bars.py\", line 96, in finish\n",
            "    super().finish()  # type: ignore\n",
            "  File \"/usr/local/lib/python3.7/dist-packages/pip/_vendor/progress/__init__.py\", line 107, in finish\n",
            "    print(file=self.file)\n",
            "RuntimeError: reentrant call inside <_io.BufferedWriter name='<stdout>'>\u001b[0m\n",
            "\u001b[Kcp: cannot stat 'kaggle.json': No such file or directory\n",
            "chmod: cannot access '/root/.kaggle/kaggle.json': No such file or directory\n",
            "Traceback (most recent call last):\n",
            "  File \"/usr/local/bin/kaggle\", line 5, in <module>\n",
            "    from kaggle.cli import main\n",
            "  File \"/usr/local/lib/python3.7/dist-packages/kaggle/__init__.py\", line 23, in <module>\n",
            "    api.authenticate()\n",
            "  File \"/usr/local/lib/python3.7/dist-packages/kaggle/api/kaggle_api_extended.py\", line 166, in authenticate\n",
            "    self.config_file, self.config_dir))\n",
            "OSError: Could not find kaggle.json. Make sure it's located in /root/.kaggle. Or use the environment method.\n",
            "Error in atexit._run_exitfuncs:\n",
            "Traceback (most recent call last):\n",
            "  File \"/usr/lib/python3.7/multiprocessing/util.py\", line 300, in _run_finalizers\n",
            "    finalizer()\n",
            "  File \"/usr/lib/python3.7/multiprocessing/util.py\", line 224, in __call__\n",
            "    res = self._callback(*self._args, **self._kwargs)\n",
            "  File \"/usr/lib/python3.7/multiprocessing/pool.py\", line 594, in _terminate_pool\n",
            "    worker_handler.join()\n",
            "  File \"/usr/lib/python3.7/threading.py\", line 1044, in join\n",
            "  File \"/usr/lib/python3.7/threading.py\", line 1060, in _wait_for_tstate_lock\n",
            "    elif lock.acquire(block, timeout):\n",
            "KeyboardInterrupt\n"
          ]
        }
      ],
      "source": [
        "!pip install -q kaggle\n",
        "!pip install --upgrade --force-reinstall --no-deps -q -U albumentations\n",
        "!pip install --upgrade --force-reinstall --no-deps -q -U opencv-python\n",
        "!pip install qudida\n",
        "\n",
        "!mkdir ~/.kaggle\n",
        "! cp kaggle.json ~/.kaggle/\n",
        "! chmod 600 ~/.kaggle/kaggle.json\n",
        "!kaggle competitions download -c carvana-image-masking-challenge"
      ]
    },
    {
      "cell_type": "code",
      "source": [
        "os.makedirs('dataset', exist_ok=True)"
      ],
      "metadata": {
        "id": "yHA2PSxVp8DP"
      },
      "execution_count": null,
      "outputs": []
    },
    {
      "cell_type": "code",
      "source": [
        ""
      ],
      "metadata": {
        "id": "esAms9xTqPsP"
      },
      "execution_count": null,
      "outputs": []
    }
  ]
}